<sdf version='1.6'>
  <model name='IRS'>
    <link name='base_link'>
      <pose frame=''>0 0 0 0 -0 0</pose>
      <inertial>
        <pose frame=''>-1e-06 -0.001089 0.012341 0 -0 0</pose>
        <mass>0.000470667</mass>
        <inertia>
          <ixx>1.38798e-05</ixx>
          <ixy>-1.47891e-11</ixy>
          <ixz>-5.39694e-11</ixz>
          <iyy>4.36045e-05</iyy>
          <iyz>6.54134e-07</iyz>
          <izz>3.32416e-05</izz>
        </inertia>
      </inertial>
      <collision name='base_link_collision'>
        <pose frame=''>0 0 0 0 -0 0</pose>
        <geometry>
          <mesh>
            <scale>1 1 1</scale>
            <uri>model://IRS/meshes/base_link.STL</uri>
          </mesh>
        </geometry>
      </collision>
      <visual name='base_link_visual'>
        <pose frame=''>0 0 0 0 -0 0</pose>
        <geometry>
          <mesh>
            <scale>1 1 1</scale>
            <uri>model://IRS/meshes/base_link.STL</uri>
          </mesh>
        </geometry>
      </visual>
    </link>
    <link name='Link_1'>
      <pose frame=''>0 -0.054291 0 1.5708 -0 0</pose>
      <inertial>
        <pose frame=''>-0.000196 0.040659 0.032962 0 -0 0</pose>
        <mass>0.0000538583</mass>
        <inertia>
          <ixx>5.58983e-06</ixx>
          <ixy>-2.4541e-07</ixy>
          <ixz>4.96925e-09</ixz>
          <iyy>2.81823e-05</iyy>
          <iyz>-3.97957e-07</iyz>
          <izz>2.89917e-05</izz>
        </inertia>
      </inertial>
      <collision name='Link_1_collision'>
        <pose frame=''>0 0 0 0 -0 0</pose>
        <geometry>
          <mesh>
            <scale>1 1 1</scale>
            <uri>model://IRS/meshes/Link_1.STL</uri>
          </mesh>
        </geometry>
      </collision>
      <visual name='Link_1_visual'>
        <pose frame=''>0 0 0 0 -0 0</pose>
        <geometry>
          <mesh>
            <scale>1 1 1</scale>
            <uri>model://IRS/meshes/Link_1.STL</uri>
          </mesh>
        </geometry>
      </visual>
    </link>
    <joint name='guia' type='prismatic'>
      <child>Link_1</child>
      <parent>base_link</parent>
      <axis>
        <xyz>0 -1 -4e-06</xyz>
        <limit>
          <lower>0</lower>
          <upper>0.015</upper>
          <effort>0.1</effort>
          <velocity>0.005</velocity>
        </limit>
        <dynamics>
          <spring_reference>0</spring_reference>
          <spring_stiffness>0</spring_stiffness>
        </dynamics>
        <use_parent_model_frame>1</use_parent_model_frame>
      </axis>
    </joint>
  </model>
</sdf>
